<?xml version="1.0"?>
<robot xmlns:xacro="http://www.ros.org/wiki/xacro" >

<xacro:include filename="inertial_macros.xacro"/>

<material name="purple">
    <color rgba="0.50 0.0 0.50 1.0"/>
</material>

<material name="orange">
    <color rgba="1 0.3 0.1 1"/>
</material>

<material name="blue">
    <color rgba="0.2 0.2 1 1"/>
</material>

<material name="black">
    <color rgba="0 0 0 1"/>
</material>

<!--base_link-->

<link name="base_link">

</link>

<!--Chassis link-->

<joint name="chassis_joint" type="fixed">
    <parent link="base_link"/>
    <child link="chassis"/>
    <axis xyz="1.0 0.0 0.0"/>
    <origin rpy="0.0 0.0 0.0" xyz="0.0 0.0 0.23"/>
</joint>

<link name="chassis">
    <visual>
        <origin xyz="0.0 0.0 0.03" rpy="0 0 0"/>
        <geometry>
            <box size="1.05 0.35 0.45"/>
        </geometry>
        <material name="purple"/>
    </visual>
     <collision>
        <origin xyz="0.0 0.0 0.03" rpy="0 0 0"/>
        <geometry>
            <box size="1.05 0.35 0.45"/>
        </geometry>
    </collision>
    <xacro:inertial_box mass="6" x="1.05" y="0.35" z="0.45">
        <origin xyz="0.0 0.0 0.03" rpy="0 0 0"/>
    </xacro:inertial_box>
</link>

<gazebo reference="chassis">
    <material>Gazebo/Purple</material>
</gazebo>

<!-- LEFT WHEEL -->

<joint name="left_wheel_joint" type="continuous">
    <parent link="base_link"/>
    <child link="left_wheel"/>
    <origin xyz="-0.16 0.24 0.1" rpy="-1.57 0.0 0.0"/>
    <axis xyz="0.0 0.0 1.0"/>
</joint>

<link name="left_wheel">
    <visual>
        <geometry>
            <cylinder length="0.13" radius="0.15" />
        </geometry>
        <material name="black"/>
    </visual>
    <collision>
        <geometry>
            <cylinder length="0.13" radius="0.15" />
        </geometry>
    </collision>
    <xacro:inertial_cylinder mass="1.5" length="0.13" radius="0.15">
        <origin xyz="0 0 0" rpy="0 0 0"/>
    </xacro:inertial_cylinder>
</link>

<gazebo reference="left_wheel">
    <material>Gazebo/Black</material>
    <mu1 value="1.0"/>
    <mu2 value="1.0"/>
</gazebo>

<!-- RIGHT WHEEL -->

<joint name="right_wheel_joint" type="continuous">
    <parent link="base_link"/>
    <child link="right_wheel"/>
    <origin xyz="-0.16 -0.24 0.1" rpy="-1.57 0.0 0.0"/>
    <axis xyz="0.0 0.0 1.0"/>
</joint>

<link name="right_wheel">
    <visual>
        <geometry>
            <cylinder length="0.13" radius="0.15" />/>
        </geometry>
        <material name="black"/>
    </visual>
    <collision>
        <geometry>
            <cylinder length="0.13" radius="0.15" />/>
        </geometry>
    </collision>
    <xacro:inertial_cylinder mass="1.5" length="0.13" radius="0.15">
        <origin xyz="0 0 0" rpy="0 0 0"/>
    </xacro:inertial_cylinder>
</link>

<gazebo reference="right_wheel">
    <material>Gazebo/Black</material>
    <mu1 value="1.0"/>
    <mu2 value="1.0"/>
</gazebo>

<!-- CASTER WHEEL -->

<joint name="caster_wheel_joint" type="fixed">
    <parent link="chassis"/>
    <child link="caster_wheel"/>
    <axis xyz="0.0 0.0 1.0"/>
    <origin xyz="0.16 0.0 -0.13" rpy="-1.57 0.0 0.0"/>
</joint>

<link name="caster_wheel">
    <visual>
        <geometry>
            <sphere radius="0.15" />
        </geometry>
        <material name="black"/>
    </visual>
    <collision>
        <geometry>
            <sphere radius="0.15" />
        </geometry>
    </collision>
    <xacro:inertial_sphere mass="3.0" radius="0.15">
        <origin xyz="0 0 0" rpy="0 0 0"/>
    </xacro:inertial_sphere>
</link>

<gazebo reference="caster_wheel">
    <material>Gazebo/Black</material>
    <mu1 value="0.001"/>
    <mu2 value="0.001"/>
</gazebo>

</robot>